2020-04-10 00:41:22,225 - ERROR - app:root - lineno:34 - select hot books error: 'studentName'
Traceback (most recent call last):
  File "/Users/chenglu/Desktop/cs411/project1/module/Flask-BookRecommend-Mysql-master/web/app.py", line 31, in root
    my_name = hot_books[0]['studentName']
KeyError: 'studentName'
2020-04-10 00:43:08,315 - ERROR - app:insertuserinfo - lineno:215 - insert user error: (1146, "Table 'cs411.studnets' doesn't exist")
Traceback (most recent call last):
  File "/Users/chenglu/Desktop/cs411/project1/module/Flask-BookRecommend-Mysql-master/web/app.py", line 212, in insertuserinfo
    mysql.exe(sql)
  File "/Users/chenglu/Desktop/cs411/project1/module/Flask-BookRecommend-Mysql-master/web/utils.py", line 54, in exe
    c.execute(sql)
  File "/usr/local/anaconda3/lib/python3.7/site-packages/pymysql/cursors.py", line 170, in execute
    result = self._query(query)
  File "/usr/local/anaconda3/lib/python3.7/site-packages/pymysql/cursors.py", line 328, in _query
    conn.query(q)
  File "/usr/local/anaconda3/lib/python3.7/site-packages/pymysql/connections.py", line 517, in query
    self._affected_rows = self._read_query_result(unbuffered=unbuffered)
  File "/usr/local/anaconda3/lib/python3.7/site-packages/pymysql/connections.py", line 732, in _read_query_result
    result.read()
  File "/usr/local/anaconda3/lib/python3.7/site-packages/pymysql/connections.py", line 1075, in read
    first_packet = self.connection._read_packet()
  File "/usr/local/anaconda3/lib/python3.7/site-packages/pymysql/connections.py", line 684, in _read_packet
    packet.check_error()
  File "/usr/local/anaconda3/lib/python3.7/site-packages/pymysql/protocol.py", line 220, in check_error
    err.raise_mysql_exception(self._data)
  File "/usr/local/anaconda3/lib/python3.7/site-packages/pymysql/err.py", line 109, in raise_mysql_exception
    raise errorclass(errno, errval)
pymysql.err.ProgrammingError: (1146, "Table 'cs411.studnets' doesn't exist")
2020-04-10 00:43:25,931 - ERROR - app:insertuserinfo - lineno:215 - insert user error: (1146, "Table 'cs411.studnets' doesn't exist")
Traceback (most recent call last):
  File "/Users/chenglu/Desktop/cs411/project1/module/Flask-BookRecommend-Mysql-master/web/app.py", line 212, in insertuserinfo
    mysql.exe(sql)
  File "/Users/chenglu/Desktop/cs411/project1/module/Flask-BookRecommend-Mysql-master/web/utils.py", line 54, in exe
    c.execute(sql)
  File "/usr/local/anaconda3/lib/python3.7/site-packages/pymysql/cursors.py", line 170, in execute
    result = self._query(query)
  File "/usr/local/anaconda3/lib/python3.7/site-packages/pymysql/cursors.py", line 328, in _query
    conn.query(q)
  File "/usr/local/anaconda3/lib/python3.7/site-packages/pymysql/connections.py", line 517, in query
    self._affected_rows = self._read_query_result(unbuffered=unbuffered)
  File "/usr/local/anaconda3/lib/python3.7/site-packages/pymysql/connections.py", line 732, in _read_query_result
    result.read()
  File "/usr/local/anaconda3/lib/python3.7/site-packages/pymysql/connections.py", line 1075, in read
    first_packet = self.connection._read_packet()
  File "/usr/local/anaconda3/lib/python3.7/site-packages/pymysql/connections.py", line 684, in _read_packet
    packet.check_error()
  File "/usr/local/anaconda3/lib/python3.7/site-packages/pymysql/protocol.py", line 220, in check_error
    err.raise_mysql_exception(self._data)
  File "/usr/local/anaconda3/lib/python3.7/site-packages/pymysql/err.py", line 109, in raise_mysql_exception
    raise errorclass(errno, errval)
pymysql.err.ProgrammingError: (1146, "Table 'cs411.studnets' doesn't exist")
2020-04-10 00:45:04,409 - ERROR - app:insertuserinfo - lineno:215 - insert user error: (1146, "Table 'cs411.studnets' doesn't exist")
Traceback (most recent call last):
  File "/Users/chenglu/Desktop/cs411/project1/module/Flask-BookRecommend-Mysql-master/web/app.py", line 212, in insertuserinfo
    mysql.exe(sql)
  File "/Users/chenglu/Desktop/cs411/project1/module/Flask-BookRecommend-Mysql-master/web/utils.py", line 54, in exe
    c.execute(sql)
  File "/usr/local/anaconda3/lib/python3.7/site-packages/pymysql/cursors.py", line 170, in execute
    result = self._query(query)
  File "/usr/local/anaconda3/lib/python3.7/site-packages/pymysql/cursors.py", line 328, in _query
    conn.query(q)
  File "/usr/local/anaconda3/lib/python3.7/site-packages/pymysql/connections.py", line 517, in query
    self._affected_rows = self._read_query_result(unbuffered=unbuffered)
  File "/usr/local/anaconda3/lib/python3.7/site-packages/pymysql/connections.py", line 732, in _read_query_result
    result.read()
  File "/usr/local/anaconda3/lib/python3.7/site-packages/pymysql/connections.py", line 1075, in read
    first_packet = self.connection._read_packet()
  File "/usr/local/anaconda3/lib/python3.7/site-packages/pymysql/connections.py", line 684, in _read_packet
    packet.check_error()
  File "/usr/local/anaconda3/lib/python3.7/site-packages/pymysql/protocol.py", line 220, in check_error
    err.raise_mysql_exception(self._data)
  File "/usr/local/anaconda3/lib/python3.7/site-packages/pymysql/err.py", line 109, in raise_mysql_exception
    raise errorclass(errno, errval)
pymysql.err.ProgrammingError: (1146, "Table 'cs411.studnets' doesn't exist")
2020-04-10 00:45:35,897 - ERROR - app:insertuserinfo - lineno:215 - insert user error: (1146, "Table 'cs411.studnets' doesn't exist")
Traceback (most recent call last):
  File "/Users/chenglu/Desktop/cs411/project1/module/Flask-BookRecommend-Mysql-master/web/app.py", line 212, in insertuserinfo
    mysql.exe(sql)
  File "/Users/chenglu/Desktop/cs411/project1/module/Flask-BookRecommend-Mysql-master/web/utils.py", line 54, in exe
    c.execute(sql)
  File "/usr/local/anaconda3/lib/python3.7/site-packages/pymysql/cursors.py", line 170, in execute
    result = self._query(query)
  File "/usr/local/anaconda3/lib/python3.7/site-packages/pymysql/cursors.py", line 328, in _query
    conn.query(q)
  File "/usr/local/anaconda3/lib/python3.7/site-packages/pymysql/connections.py", line 517, in query
    self._affected_rows = self._read_query_result(unbuffered=unbuffered)
  File "/usr/local/anaconda3/lib/python3.7/site-packages/pymysql/connections.py", line 732, in _read_query_result
    result.read()
  File "/usr/local/anaconda3/lib/python3.7/site-packages/pymysql/connections.py", line 1075, in read
    first_packet = self.connection._read_packet()
  File "/usr/local/anaconda3/lib/python3.7/site-packages/pymysql/connections.py", line 684, in _read_packet
    packet.check_error()
  File "/usr/local/anaconda3/lib/python3.7/site-packages/pymysql/protocol.py", line 220, in check_error
    err.raise_mysql_exception(self._data)
  File "/usr/local/anaconda3/lib/python3.7/site-packages/pymysql/err.py", line 109, in raise_mysql_exception
    raise errorclass(errno, errval)
pymysql.err.ProgrammingError: (1146, "Table 'cs411.studnets' doesn't exist")
2020-04-10 00:45:47,264 - ERROR - app:insertuserinfo - lineno:215 - insert user error: (1146, "Table 'cs411.studnets' doesn't exist")
Traceback (most recent call last):
  File "/Users/chenglu/Desktop/cs411/project1/module/Flask-BookRecommend-Mysql-master/web/app.py", line 212, in insertuserinfo
    mysql.exe(sql)
  File "/Users/chenglu/Desktop/cs411/project1/module/Flask-BookRecommend-Mysql-master/web/utils.py", line 54, in exe
    c.execute(sql)
  File "/usr/local/anaconda3/lib/python3.7/site-packages/pymysql/cursors.py", line 170, in execute
    result = self._query(query)
  File "/usr/local/anaconda3/lib/python3.7/site-packages/pymysql/cursors.py", line 328, in _query
    conn.query(q)
  File "/usr/local/anaconda3/lib/python3.7/site-packages/pymysql/connections.py", line 517, in query
    self._affected_rows = self._read_query_result(unbuffered=unbuffered)
  File "/usr/local/anaconda3/lib/python3.7/site-packages/pymysql/connections.py", line 732, in _read_query_result
    result.read()
  File "/usr/local/anaconda3/lib/python3.7/site-packages/pymysql/connections.py", line 1075, in read
    first_packet = self.connection._read_packet()
  File "/usr/local/anaconda3/lib/python3.7/site-packages/pymysql/connections.py", line 684, in _read_packet
    packet.check_error()
  File "/usr/local/anaconda3/lib/python3.7/site-packages/pymysql/protocol.py", line 220, in check_error
    err.raise_mysql_exception(self._data)
  File "/usr/local/anaconda3/lib/python3.7/site-packages/pymysql/err.py", line 109, in raise_mysql_exception
    raise errorclass(errno, errval)
pymysql.err.ProgrammingError: (1146, "Table 'cs411.studnets' doesn't exist")
2020-04-10 00:46:32,024 - ERROR - app:insertuserinfo - lineno:219 - insert user error: (1146, "Table 'cs411.studnets' doesn't exist")
Traceback (most recent call last):
  File "/Users/chenglu/Desktop/cs411/project1/module/Flask-BookRecommend-Mysql-master/web/app.py", line 212, in insertuserinfo
    mysql.exe(sql)
  File "/Users/chenglu/Desktop/cs411/project1/module/Flask-BookRecommend-Mysql-master/web/utils.py", line 54, in exe
    c.execute(sql)
  File "/usr/local/anaconda3/lib/python3.7/site-packages/pymysql/cursors.py", line 170, in execute
    result = self._query(query)
  File "/usr/local/anaconda3/lib/python3.7/site-packages/pymysql/cursors.py", line 328, in _query
    conn.query(q)
  File "/usr/local/anaconda3/lib/python3.7/site-packages/pymysql/connections.py", line 517, in query
    self._affected_rows = self._read_query_result(unbuffered=unbuffered)
  File "/usr/local/anaconda3/lib/python3.7/site-packages/pymysql/connections.py", line 732, in _read_query_result
    result.read()
  File "/usr/local/anaconda3/lib/python3.7/site-packages/pymysql/connections.py", line 1075, in read
    first_packet = self.connection._read_packet()
  File "/usr/local/anaconda3/lib/python3.7/site-packages/pymysql/connections.py", line 684, in _read_packet
    packet.check_error()
  File "/usr/local/anaconda3/lib/python3.7/site-packages/pymysql/protocol.py", line 220, in check_error
    err.raise_mysql_exception(self._data)
  File "/usr/local/anaconda3/lib/python3.7/site-packages/pymysql/err.py", line 109, in raise_mysql_exception
    raise errorclass(errno, errval)
pymysql.err.ProgrammingError: (1146, "Table 'cs411.studnets' doesn't exist")
2020-04-10 00:46:54,118 - ERROR - app:insertuserinfo - lineno:219 - insert user error: (1146, "Table 'cs411.studnets' doesn't exist")
Traceback (most recent call last):
  File "/Users/chenglu/Desktop/cs411/project1/module/Flask-BookRecommend-Mysql-master/web/app.py", line 212, in insertuserinfo
    mysql.exe(sql)
  File "/Users/chenglu/Desktop/cs411/project1/module/Flask-BookRecommend-Mysql-master/web/utils.py", line 54, in exe
    c.execute(sql)
  File "/usr/local/anaconda3/lib/python3.7/site-packages/pymysql/cursors.py", line 170, in execute
    result = self._query(query)
  File "/usr/local/anaconda3/lib/python3.7/site-packages/pymysql/cursors.py", line 328, in _query
    conn.query(q)
  File "/usr/local/anaconda3/lib/python3.7/site-packages/pymysql/connections.py", line 517, in query
    self._affected_rows = self._read_query_result(unbuffered=unbuffered)
  File "/usr/local/anaconda3/lib/python3.7/site-packages/pymysql/connections.py", line 732, in _read_query_result
    result.read()
  File "/usr/local/anaconda3/lib/python3.7/site-packages/pymysql/connections.py", line 1075, in read
    first_packet = self.connection._read_packet()
  File "/usr/local/anaconda3/lib/python3.7/site-packages/pymysql/connections.py", line 684, in _read_packet
    packet.check_error()
  File "/usr/local/anaconda3/lib/python3.7/site-packages/pymysql/protocol.py", line 220, in check_error
    err.raise_mysql_exception(self._data)
  File "/usr/local/anaconda3/lib/python3.7/site-packages/pymysql/err.py", line 109, in raise_mysql_exception
    raise errorclass(errno, errval)
pymysql.err.ProgrammingError: (1146, "Table 'cs411.studnets' doesn't exist")
2020-04-10 00:47:03,404 - ERROR - app:insertuserinfo - lineno:219 - insert user error: (1146, "Table 'cs411.studnets' doesn't exist")
Traceback (most recent call last):
  File "/Users/chenglu/Desktop/cs411/project1/module/Flask-BookRecommend-Mysql-master/web/app.py", line 212, in insertuserinfo
    mysql.exe(sql)
  File "/Users/chenglu/Desktop/cs411/project1/module/Flask-BookRecommend-Mysql-master/web/utils.py", line 54, in exe
    c.execute(sql)
  File "/usr/local/anaconda3/lib/python3.7/site-packages/pymysql/cursors.py", line 170, in execute
    result = self._query(query)
  File "/usr/local/anaconda3/lib/python3.7/site-packages/pymysql/cursors.py", line 328, in _query
    conn.query(q)
  File "/usr/local/anaconda3/lib/python3.7/site-packages/pymysql/connections.py", line 517, in query
    self._affected_rows = self._read_query_result(unbuffered=unbuffered)
  File "/usr/local/anaconda3/lib/python3.7/site-packages/pymysql/connections.py", line 732, in _read_query_result
    result.read()
  File "/usr/local/anaconda3/lib/python3.7/site-packages/pymysql/connections.py", line 1075, in read
    first_packet = self.connection._read_packet()
  File "/usr/local/anaconda3/lib/python3.7/site-packages/pymysql/connections.py", line 684, in _read_packet
    packet.check_error()
  File "/usr/local/anaconda3/lib/python3.7/site-packages/pymysql/protocol.py", line 220, in check_error
    err.raise_mysql_exception(self._data)
  File "/usr/local/anaconda3/lib/python3.7/site-packages/pymysql/err.py", line 109, in raise_mysql_exception
    raise errorclass(errno, errval)
pymysql.err.ProgrammingError: (1146, "Table 'cs411.studnets' doesn't exist")
2020-04-10 00:47:13,756 - ERROR - app:insertuserinfo - lineno:219 - insert user error: (1146, "Table 'cs411.studnets' doesn't exist")
Traceback (most recent call last):
  File "/Users/chenglu/Desktop/cs411/project1/module/Flask-BookRecommend-Mysql-master/web/app.py", line 212, in insertuserinfo
    mysql.exe(sql)
  File "/Users/chenglu/Desktop/cs411/project1/module/Flask-BookRecommend-Mysql-master/web/utils.py", line 54, in exe
    c.execute(sql)
  File "/usr/local/anaconda3/lib/python3.7/site-packages/pymysql/cursors.py", line 170, in execute
    result = self._query(query)
  File "/usr/local/anaconda3/lib/python3.7/site-packages/pymysql/cursors.py", line 328, in _query
    conn.query(q)
  File "/usr/local/anaconda3/lib/python3.7/site-packages/pymysql/connections.py", line 517, in query
    self._affected_rows = self._read_query_result(unbuffered=unbuffered)
  File "/usr/local/anaconda3/lib/python3.7/site-packages/pymysql/connections.py", line 732, in _read_query_result
    result.read()
  File "/usr/local/anaconda3/lib/python3.7/site-packages/pymysql/connections.py", line 1075, in read
    first_packet = self.connection._read_packet()
  File "/usr/local/anaconda3/lib/python3.7/site-packages/pymysql/connections.py", line 684, in _read_packet
    packet.check_error()
  File "/usr/local/anaconda3/lib/python3.7/site-packages/pymysql/protocol.py", line 220, in check_error
    err.raise_mysql_exception(self._data)
  File "/usr/local/anaconda3/lib/python3.7/site-packages/pymysql/err.py", line 109, in raise_mysql_exception
    raise errorclass(errno, errval)
pymysql.err.ProgrammingError: (1146, "Table 'cs411.studnets' doesn't exist")
2020-04-10 00:49:32,910 - ERROR - app:insertuserinfo - lineno:219 - insert user error: (1146, "Table 'cs411.studnets' doesn't exist")
Traceback (most recent call last):
  File "/Users/chenglu/Desktop/cs411/project1/module/Flask-BookRecommend-Mysql-master/web/app.py", line 212, in insertuserinfo
    mysql.exe(sql)
  File "/Users/chenglu/Desktop/cs411/project1/module/Flask-BookRecommend-Mysql-master/web/utils.py", line 54, in exe
    c.execute(sql)
  File "/usr/local/anaconda3/lib/python3.7/site-packages/pymysql/cursors.py", line 170, in execute
    result = self._query(query)
  File "/usr/local/anaconda3/lib/python3.7/site-packages/pymysql/cursors.py", line 328, in _query
    conn.query(q)
  File "/usr/local/anaconda3/lib/python3.7/site-packages/pymysql/connections.py", line 517, in query
    self._affected_rows = self._read_query_result(unbuffered=unbuffered)
  File "/usr/local/anaconda3/lib/python3.7/site-packages/pymysql/connections.py", line 732, in _read_query_result
    result.read()
  File "/usr/local/anaconda3/lib/python3.7/site-packages/pymysql/connections.py", line 1075, in read
    first_packet = self.connection._read_packet()
  File "/usr/local/anaconda3/lib/python3.7/site-packages/pymysql/connections.py", line 684, in _read_packet
    packet.check_error()
  File "/usr/local/anaconda3/lib/python3.7/site-packages/pymysql/protocol.py", line 220, in check_error
    err.raise_mysql_exception(self._data)
  File "/usr/local/anaconda3/lib/python3.7/site-packages/pymysql/err.py", line 109, in raise_mysql_exception
    raise errorclass(errno, errval)
pymysql.err.ProgrammingError: (1146, "Table 'cs411.studnets' doesn't exist")
2020-04-10 00:50:16,703 - INFO - app:insertuserinfo - lineno:213 - insert user success,sql: insert into Students 
            values (6, 'Leo', 'male', 'master', 'me', 4.0)
2020-04-10 00:51:29,988 - INFO - app:insertuserinfo - lineno:213 - insert user success,sql: insert into Students 
            values (7, 'Zora', 'female', 'freshman', 'ce', 3.80)
2020-04-10 01:02:16,689 - ERROR - app:insertuserinfo - lineno:219 - insert user error: (1054, "Unknown column 'None' in 'field list'")
Traceback (most recent call last):
  File "/Users/chenglu/Desktop/cs411/project1/module/Flask-BookRecommend-Mysql-master/web/app.py", line 212, in insertuserinfo
    mysql.exe(sql)
  File "/Users/chenglu/Desktop/cs411/project1/module/Flask-BookRecommend-Mysql-master/web/utils.py", line 54, in exe
    c.execute(sql)
  File "/usr/local/anaconda3/lib/python3.7/site-packages/pymysql/cursors.py", line 170, in execute
    result = self._query(query)
  File "/usr/local/anaconda3/lib/python3.7/site-packages/pymysql/cursors.py", line 328, in _query
    conn.query(q)
  File "/usr/local/anaconda3/lib/python3.7/site-packages/pymysql/connections.py", line 517, in query
    self._affected_rows = self._read_query_result(unbuffered=unbuffered)
  File "/usr/local/anaconda3/lib/python3.7/site-packages/pymysql/connections.py", line 732, in _read_query_result
    result.read()
  File "/usr/local/anaconda3/lib/python3.7/site-packages/pymysql/connections.py", line 1075, in read
    first_packet = self.connection._read_packet()
  File "/usr/local/anaconda3/lib/python3.7/site-packages/pymysql/connections.py", line 684, in _read_packet
    packet.check_error()
  File "/usr/local/anaconda3/lib/python3.7/site-packages/pymysql/protocol.py", line 220, in check_error
    err.raise_mysql_exception(self._data)
  File "/usr/local/anaconda3/lib/python3.7/site-packages/pymysql/err.py", line 109, in raise_mysql_exception
    raise errorclass(errno, errval)
pymysql.err.InternalError: (1054, "Unknown column 'None' in 'field list'")
2020-04-10 01:02:29,603 - INFO - app:deleteuserinfo - lineno:241 - delete user success,sql:DELETE  FROM Students where UIN=6 
2020-04-10 01:02:39,771 - INFO - app:deleteuserinfo - lineno:241 - delete user success,sql:DELETE  FROM Students where UIN=7 
2020-04-10 01:03:15,408 - INFO - app:insertuserinfo - lineno:213 - insert user success,sql: insert into Students 
            values (6, 'Leo', 'male', 'master', 'me', 4.0)
2020-04-10 01:03:19,447 - INFO - app:deleteuserinfo - lineno:241 - delete user success,sql:DELETE  FROM Students where UIN=6 
2020-04-10 01:04:39,538 - INFO - app:deleteuserinfo - lineno:241 - delete user success,sql:DELETE  FROM Students where UIN=6 
2020-04-10 01:04:44,893 - INFO - app:deleteuserinfo - lineno:241 - delete user success,sql:DELETE  FROM Students where UIN=6 
2020-04-10 01:04:45,035 - INFO - app:deleteuserinfo - lineno:241 - delete user success,sql:DELETE  FROM Students where UIN=6 
2020-04-10 01:04:45,163 - INFO - app:deleteuserinfo - lineno:241 - delete user success,sql:DELETE  FROM Students where UIN=6 
2020-04-10 01:04:45,296 - INFO - app:deleteuserinfo - lineno:241 - delete user success,sql:DELETE  FROM Students where UIN=6 
2020-04-10 01:14:34,866 - INFO - app:insertuserinfo - lineno:213 - insert user success,sql: insert into Students 
            values (6, 'Leo', 'male', 'master', 'me', 4.0)
2020-04-10 01:15:08,162 - INFO - app:updateuserinfo - lineno:256 - update user success,sql: update Students 
                      set studentName='Leo', Gender='male', Standing='master', Major='me', GPA='3.80' 
            where UIN = '6' 
2020-04-10 01:15:23,976 - INFO - app:deleteuserinfo - lineno:284 - delete user success,sql:DELETE  FROM Students where UIN=6 
2020-04-10 01:15:35,378 - ERROR - app:root - lineno:34 - select hot books error: 'studentName'
Traceback (most recent call last):
  File "/Users/chenglu/Desktop/cs411/project1/module/Flask-BookRecommend-Mysql-master/web/app.py", line 31, in root
    my_name = hot_books[0]['studentName']
KeyError: 'studentName'
2020-04-10 01:33:08,461 - ERROR - app:root - lineno:34 - select hot books error: 'studentName'
Traceback (most recent call last):
  File "/Users/chenglu/Desktop/cs411/project1/module/Flask-BookRecommend-Mysql-master/web/app.py", line 31, in root
    my_name = hot_books[0]['studentName']
KeyError: 'studentName'
2020-04-10 01:33:37,172 - ERROR - app:root - lineno:34 - select hot books error: 'studentName'
Traceback (most recent call last):
  File "/Users/chenglu/Desktop/cs411/project1/module/Flask-BookRecommend-Mysql-master/web/app.py", line 31, in root
    my_name = hot_books[0]['studentName']
KeyError: 'studentName'
2020-04-10 01:49:02,236 - ERROR - app:root - lineno:34 - select hot books error: 'studentName'
Traceback (most recent call last):
  File "/Users/chenglu/Desktop/cs411/project1/module/Flask-BookRecommend-Mysql-master/web/app.py", line 31, in root
    my_name = hot_books[0]['studentName']
KeyError: 'studentName'
2020-04-10 01:58:12,923 - ERROR - app:root - lineno:34 - select hot books error: 'studentName'
Traceback (most recent call last):
  File "/Users/chenglu/Desktop/cs411/project1/module/Flask-BookRecommend-Mysql-master/web/app.py", line 31, in root
    my_name = hot_books[0]['studentName']
KeyError: 'studentName'
2020-04-10 01:58:12,923 - ERROR - app:root - lineno:34 - select hot books error: 'studentName'
Traceback (most recent call last):
  File "/Users/chenglu/Desktop/cs411/project1/module/Flask-BookRecommend-Mysql-master/web/app.py", line 31, in root
    my_name = hot_books[0]['studentName']
KeyError: 'studentName'
2020-04-10 01:58:12,923 - ERROR - app:root - lineno:34 - select hot books error: 'studentName'
Traceback (most recent call last):
  File "/Users/chenglu/Desktop/cs411/project1/module/Flask-BookRecommend-Mysql-master/web/app.py", line 31, in root
    my_name = hot_books[0]['studentName']
KeyError: 'studentName'
2020-04-10 01:58:12,923 - ERROR - app:root - lineno:34 - select hot books error: 'studentName'
Traceback (most recent call last):
  File "/Users/chenglu/Desktop/cs411/project1/module/Flask-BookRecommend-Mysql-master/web/app.py", line 31, in root
    my_name = hot_books[0]['studentName']
KeyError: 'studentName'
2020-04-10 01:58:12,923 - ERROR - app:root - lineno:34 - select hot books error: 'studentName'
Traceback (most recent call last):
  File "/Users/chenglu/Desktop/cs411/project1/module/Flask-BookRecommend-Mysql-master/web/app.py", line 31, in root
    my_name = hot_books[0]['studentName']
KeyError: 'studentName'
2020-04-10 01:58:12,923 - ERROR - app:root - lineno:34 - select hot books error: 'studentName'
Traceback (most recent call last):
  File "/Users/chenglu/Desktop/cs411/project1/module/Flask-BookRecommend-Mysql-master/web/app.py", line 31, in root
    my_name = hot_books[0]['studentName']
KeyError: 'studentName'
2020-04-10 01:58:12,923 - ERROR - app:root - lineno:34 - select hot books error: 'studentName'
Traceback (most recent call last):
  File "/Users/chenglu/Desktop/cs411/project1/module/Flask-BookRecommend-Mysql-master/web/app.py", line 31, in root
    my_name = hot_books[0]['studentName']
KeyError: 'studentName'
2020-04-10 01:58:15,497 - ERROR - app:root - lineno:34 - select hot books error: 'studentName'
Traceback (most recent call last):
  File "/Users/chenglu/Desktop/cs411/project1/module/Flask-BookRecommend-Mysql-master/web/app.py", line 31, in root
    my_name = hot_books[0]['studentName']
KeyError: 'studentName'
2020-04-10 01:58:35,507 - ERROR - app:root - lineno:34 - select hot books error: 'studentName'
Traceback (most recent call last):
  File "/Users/chenglu/Desktop/cs411/project1/module/Flask-BookRecommend-Mysql-master/web/app.py", line 31, in root
    my_name = hot_books[0]['studentName']
KeyError: 'studentName'
2020-04-10 02:02:02,158 - ERROR - app:root - lineno:34 - select hot books error: 'studentName'
Traceback (most recent call last):
  File "/Users/chenglu/Desktop/cs411/project1/module/Flask-BookRecommend-Mysql-master/web/app.py", line 31, in root
    my_name = hot_books[0]['studentName']
KeyError: 'studentName'
2020-04-10 02:13:04,902 - ERROR - app:root - lineno:34 - select hot books error: 'studentName'
Traceback (most recent call last):
  File "/Users/chenglu/Desktop/cs411/project1/module/Flask-BookRecommend-Mysql-master/web/app.py", line 31, in root
    my_name = hot_books[0]['studentName']
KeyError: 'studentName'
2020-04-10 02:15:44,783 - ERROR - app:insertuserinfo - lineno:245 - insert user error: (1064, "You have an error in your SQL syntax; check the manual that corresponds to your MySQL server version for the right syntax to use near ')' at line 2")
Traceback (most recent call last):
  File "/Users/chenglu/Desktop/cs411/project1/module/Flask-BookRecommend-Mysql-master/web/app.py", line 238, in insertuserinfo
    mysql.exe(sql)
  File "/Users/chenglu/Desktop/cs411/project1/module/Flask-BookRecommend-Mysql-master/web/utils.py", line 54, in exe
    c.execute(sql)
  File "/usr/local/anaconda3/lib/python3.7/site-packages/pymysql/cursors.py", line 170, in execute
    result = self._query(query)
  File "/usr/local/anaconda3/lib/python3.7/site-packages/pymysql/cursors.py", line 328, in _query
    conn.query(q)
  File "/usr/local/anaconda3/lib/python3.7/site-packages/pymysql/connections.py", line 517, in query
    self._affected_rows = self._read_query_result(unbuffered=unbuffered)
  File "/usr/local/anaconda3/lib/python3.7/site-packages/pymysql/connections.py", line 732, in _read_query_result
    result.read()
  File "/usr/local/anaconda3/lib/python3.7/site-packages/pymysql/connections.py", line 1075, in read
    first_packet = self.connection._read_packet()
  File "/usr/local/anaconda3/lib/python3.7/site-packages/pymysql/connections.py", line 684, in _read_packet
    packet.check_error()
  File "/usr/local/anaconda3/lib/python3.7/site-packages/pymysql/protocol.py", line 220, in check_error
    err.raise_mysql_exception(self._data)
  File "/usr/local/anaconda3/lib/python3.7/site-packages/pymysql/err.py", line 109, in raise_mysql_exception
    raise errorclass(errno, errval)
pymysql.err.ProgrammingError: (1064, "You have an error in your SQL syntax; check the manual that corresponds to your MySQL server version for the right syntax to use near ')' at line 2")
2020-04-10 02:15:50,828 - ERROR - app:root - lineno:34 - select hot books error: 'studentName'
Traceback (most recent call last):
  File "/Users/chenglu/Desktop/cs411/project1/module/Flask-BookRecommend-Mysql-master/web/app.py", line 31, in root
    my_name = hot_books[0]['studentName']
KeyError: 'studentName'
2020-04-10 02:15:59,003 - INFO - app:insertuserinfo - lineno:239 - insert user success,sql: insert into Students 
            values (6, 'Leo', 'male', 'master', 'me', 4.0)
2020-04-10 02:16:23,110 - INFO - app:updateuserinfo - lineno:282 - update user success,sql: update Students 
                      set studentName='Leo', Gender='male', Standing='master', Major='me', GPA='3.80' 
            where UIN = '6' 
2020-04-10 02:16:29,890 - INFO - app:deleteuserinfo - lineno:310 - delete user success,sql:DELETE  FROM Students where UIN=6 
2020-04-10 02:20:19,167 - ERROR - app:root - lineno:34 - select hot books error: 'studentName'
Traceback (most recent call last):
  File "/Users/chenglu/Desktop/cs411/project1/module/Flask-BookRecommend-Mysql-master/web/app.py", line 31, in root
    my_name = hot_books[0]['studentName']
KeyError: 'studentName'
2020-04-10 02:20:43,138 - ERROR - app:root - lineno:34 - select hot books error: 'studentName'
Traceback (most recent call last):
  File "/Users/chenglu/Desktop/cs411/project1/module/Flask-BookRecommend-Mysql-master/web/app.py", line 31, in root
    my_name = hot_books[0]['studentName']
KeyError: 'studentName'
2020-04-10 02:22:46,447 - ERROR - app:root - lineno:34 - select hot books error: 'studentName'
Traceback (most recent call last):
  File "/Users/chenglu/Desktop/cs411/project1/module/Flask-BookRecommend-Mysql-master/web/app.py", line 31, in root
    my_name = hot_books[0]['studentName']
KeyError: 'studentName'
2020-04-10 02:23:21,549 - INFO - app:deleteuserinfo - lineno:310 - delete user success,sql:DELETE  FROM Students where UIN=6 
2020-04-10 02:28:51,725 - ERROR - app:root - lineno:34 - select hot books error: 'studentName'
Traceback (most recent call last):
  File "/Users/chenglu/Desktop/cs411/project1/module/Flask-BookRecommend-Mysql-master/web/app.py", line 31, in root
    my_name = hot_books[0]['studentName']
KeyError: 'studentName'
2020-04-10 14:30:42,375 - INFO - app:insertuserinfo - lineno:239 - insert user success,sql: insert into Students 
            values (6, 'Leo', 'male', 'master', 'me', 4.0)
2020-04-10 14:31:11,064 - INFO - app:updateuserinfo - lineno:282 - update user success,sql: update Students 
                      set studentName='Leo', Gender='male', Standing='master', Major='me', GPA='3.80' 
            where UIN = '6' 
2020-04-10 14:31:41,963 - INFO - app:deleteuserinfo - lineno:310 - delete user success,sql:DELETE  FROM Students where UIN=6 
2020-04-10 14:41:10,221 - ERROR - app:root - lineno:34 - select hot books error: 'studentName'
Traceback (most recent call last):
  File "/Users/chenglu/Desktop/cs411/project1/module/Flask-BookRecommend-Mysql-master/web/app.py", line 31, in root
    my_name = hot_books[0]['studentName']
KeyError: 'studentName'
2020-04-10 14:44:17,125 - INFO - app:insertuserinfo - lineno:239 - insert user success,sql: insert into Students 
            values (6, 'Leo', 'male', 'master', 'ce', 4.0)
2020-04-10 14:44:31,918 - INFO - app:updateuserinfo - lineno:282 - update user success,sql: update Students 
                      set studentName='Leo', Gender='male', Standing='master', Major='me', GPA='3.80' 
            where UIN = '6' 
2020-04-10 14:44:48,762 - INFO - app:deleteuserinfo - lineno:310 - delete user success,sql:DELETE  FROM Students where UIN=6 
2020-04-10 15:04:33,090 - ERROR - app:root - lineno:34 - select hot books error: 'studentName'
Traceback (most recent call last):
  File "/Users/chenglu/Desktop/cs411/project1/module/Flask-BookRecommend-Mysql-master/web/app.py", line 31, in root
    my_name = hot_books[0]['studentName']
KeyError: 'studentName'
2020-04-10 15:04:42,360 - ERROR - app:root - lineno:34 - select hot books error: 'studentName'
Traceback (most recent call last):
  File "/Users/chenglu/Desktop/cs411/project1/module/Flask-BookRecommend-Mysql-master/web/app.py", line 31, in root
    my_name = hot_books[0]['studentName']
KeyError: 'studentName'
2020-04-10 15:05:04,329 - ERROR - app:root - lineno:34 - select hot books error: 'studentName'
Traceback (most recent call last):
  File "/Users/chenglu/Desktop/cs411/project1/module/Flask-BookRecommend-Mysql-master/web/app.py", line 31, in root
    my_name = hot_books[0]['studentName']
KeyError: 'studentName'
2020-04-10 15:11:17,891 - ERROR - app:root - lineno:34 - select hot books error: 'studentName'
Traceback (most recent call last):
  File "/Users/chenglu/Desktop/cs411/project1/module/Flask-BookRecommend-Mysql-master/web/app.py", line 31, in root
    my_name = hot_books[0]['studentName']
KeyError: 'studentName'
